Workbook

Sheet Start Here
B1: Your Security Assessment Questionnaire Template
B4: How to use this template:
B5: Step 1 Add Questions and Tag Frameworks | C5: Use the Your Draft tab to capture the security questions your organization commonly receives. The questions provided are examples and should be customized to reflect real‑world inquiries. For each question, tag the framework(s) it is typically answered in (SIG Core, CAIQ, and/or VSAQ) to enable consistent reuse across questionnaires.
B6: Step 2 Enter Your Response for Each Question | C6: For each question, record a single control status (Yes / No / Partial) based on current implementation. Use Partial when a control exists but is incomplete, inconsistently applied, or missing documentation or scope. Provide a concise explanation with a remediation plan, if necessary, and reference existing evidence where applicable.
B7: Step 3 Assign Owners and Maintain Accuracy | C7: Assign an Owner responsible for the accuracy of each answer and track Last Reviewed and Next Review dates. For each response, record a maturity score to reflect how fully the control is implemented. Update responses and scores when controls change or evidence expires to keep answers consistent, defensible, and useful for tracking improvement over time.
B8: Step 4 Review the Dashboard Regulary | C8: Use the Dashboard tab to monitor the overall state of your security program. The dashboard automatically summarizes control status, maturity, and coverage by category based on the data in Your Draft. Review this view regularly to identify gaps, prioritize improvements, track progress over time, and support leadership or audit discussions.
B10: Automatically respond to high-stakes security questionnaires with Loopio.
B11: Book a Demo

Sheet Dashboard
B1: Your Security Program Dashboard
B3: Fill in Your Draft to keep this view current. Use it in team meetings and leadership reviews.
B5: Program Summary
B6: Total Questions | C6: Approved | D6: Draft | E6: Needs Update | F6: Avg. Maturity
B7: =COUNTIFS('Your Draft'!D:D, "<>", 'Your Draft'!D:D, "<>Question") -> 142 | C7: =COUNTIF('Your Draft'!L:L, "*Approved") -> 0 | D7: =COUNTIF('Your Draft'!L:L, "*Draft") -> 0 | E7: =COUNTIF('Your Draft'!L:L, "*Needs Update") -> 0 | F7: =IFERROR(AVERAGE('Your Draft'!M:M), 0) -> 0
B10: Control Status by Category
B11: Category | C11: Total | D11: Yes | E11: Partial | F11: No
B12: Governance & Risk | C12: =COUNTIF('Your Draft'!C:C, "*Governance & Risk") -> 10 | D12: =COUNTIF('Your Draft'!H14:H23, "*Yes") -> 0 | E12: =COUNTIF('Your Draft'!H14:H23, "*Partial") -> 0 | F12: =COUNTIF('Your Draft'!H14:H23, "*No") -> 0
B13: Asset Management | C13: =COUNTIF('Your Draft'!C:C, "*Asset Management") -> 5 | D13: =COUNTIF('Your Draft'!H25:H29, "*Yes") -> 0 | E13: =COUNTIF('Your Draft'!H25:H29, "*Partial") -> 0 | F13: =COUNTIF('Your Draft'!H25:H29, "*No") -> 0
B14: Access Control & Identity | C14: =COUNTIF('Your Draft'!C:C, "*Access Control & Identity") -> 16 | D14: =COUNTIF('Your Draft'!H31:H46, "*Yes") -> 0 | E14: =COUNTIF('Your Draft'!H31:H46, "*Partial") -> 0 | F14: =COUNTIF('Your Draft'!H31:H46, "*No") -> 0
B15: Data Security & Encryption | C15: =COUNTIF('Your Draft'!C:C, "*Data Security & Encryption") -> 18 | D15: =COUNTIF('Your Draft'!H48:H65, "*Yes") -> 0 | E15: =COUNTIF('Your Draft'!H48:H65, "*Partial") -> 0 | F15: =COUNTIF('Your Draft'!H48:H65, "*No") -> 0
B16: Application Security | C16: =COUNTIF('Your Draft'!C:C, "*Application Security") -> 13 | D16: =COUNTIF('Your Draft'!H67:H79, "*Yes") -> 0 | E16: =COUNTIF('Your Draft'!H67:H79, "*Partial") -> 0 | F16: =COUNTIF('Your Draft'!H67:H79, "*No") -> 0
B17: Network & Infrastructure | C17: =COUNTIF('Your Draft'!C:C, "*Network & Infrastructure") -> 22 | D17: =COUNTIF('Your Draft'!H81:H102, "*Yes") -> 0 | E17: =COUNTIF('Your Draft'!H81:H102, "*Partial") -> 0 | F17: =COUNTIF('Your Draft'!H81:H102, "*No") -> 0
B18: Monitoring & Logging | C18: =COUNTIF('Your Draft'!C:C, "*Monitoring & Logging") -> 10 | D18: =COUNTIF('Your Draft'!H104:H113, "*Yes") -> 0 | E18: =COUNTIF('Your Draft'!H104:H113, "*Partial") -> 0 | F18: =COUNTIF('Your Draft'!H104:H113, "*No") -> 0
B19: Incident Response | C19: =COUNTIF('Your Draft'!C:C, "*Incident Response") -> 10 | D19: =COUNTIF('Your Draft'!H115:H124, "*Yes") -> 0 | E19: =COUNTIF('Your Draft'!H115:H124, "*Partial") -> 0 | F19: =COUNTIF('Your Draft'!H115:H124, "*No") -> 0
B20: Business Continuity | C20: =COUNTIF('Your Draft'!C:C, "*Business Continuity") -> 10 | D20: =COUNTIF('Your Draft'!H126:H135, "*Yes") -> 0 | E20: =COUNTIF('Your Draft'!H126:H135, "*Partial") -> 0 | F20: =COUNTIF('Your Draft'!H126:H135, "*No") -> 0
B21: Physical Security | C21: =COUNTIF('Your Draft'!C:C, "*Physical Security") -> 5 | D21: =COUNTIF('Your Draft'!H137:H141, "*Yes") -> 0 | E21: =COUNTIF('Your Draft'!H137:H141, "*Partial") -> 0 | F21: =COUNTIF('Your Draft'!H137:H141, "*No") -> 0
B22: Third-Party & Supply Chain | C22: =COUNTIF('Your Draft'!C:C, "*Third-Party & Supply Chain") -> 14 | D22: =COUNTIF('Your Draft'!H143:H156, "*Yes") -> 0 | E22: =COUNTIF('Your Draft'!H143:H156, "*Partial") -> 0 | F22: =COUNTIF('Your Draft'!H143:H156, "*No") -> 0
B23: Employee & HR Controls | C23: =COUNTIF('Your Draft'!C:C, "*Employee & HR Controls") -> 4 | D23: =COUNTIF('Your Draft'!H158:H161, "*Yes") -> 0 | E23: =COUNTIF('Your Draft'!H158:H161, "*Partial") -> 0 | F23: =COUNTIF('Your Draft'!H158:H161, "*No") -> 0
B24: Compliance & Certifications | C24: =COUNTIF('Your Draft'!C:C, "*Compliance & Certifications") -> 5 | D24: =COUNTIF('Your Draft'!H163:H167, "*Yes") -> 0 | E24: =COUNTIF('Your Draft'!H163:H167, "*Partial") -> 0 | F24: =COUNTIF('Your Draft'!H163:H167, "*No") -> 0

Sheet Your Draft
B1: Your Security Assessment Questionnaire Template - Draft
B4: Tips for using this template:
B5: 1. Be transparent; evaluators look for trust and maturity, not a "Yes" to everything.
B6: 2. Check for multi-part requirements and answer "Partial" if any part is missing.
B7: 3. Reference evidence, such as "See SOC 2 Type II report, CC6.1–CC6.8."
B8: 4. Keep explanations clear and concise for the assessed service and environment.
B11: QUESTION | E11: FRAMEWORKS | H11: RESPONSE | K11: INTERNAL TRACKING
B12: # | C12: Category | D12: Question | E12: SIG | F12: CAIQ | G12: VSAQ | H12: Control Status | I12: Explanation / Evidence | J12: Responsibility (CAIQ Responses) | K12: Owner | L12: Status | M12: Maturity (1–5) | N12: Last Reviewed | O12: Next Review | P12: Evidence Link
B13: GOVERNANCE & RISK
B14: 1 | C14: Governance & Risk | D14: Does the organization maintain formally approved information security policies? | E14: TRUE | F14: FALSE | G14: TRUE
B15: 2 | C15: Governance & Risk | D15: Are information security roles and responsibilities documented? | E15: TRUE | F15: FALSE | G15: TRUE
B16: 3 | C16: Governance & Risk | D16: Is executive management involved in information security oversight? | E16: TRUE | F16: FALSE | G16: TRUE
B17: 4 | C17: Governance & Risk | D17: Are security policies communicated to all employees? | E17: TRUE | F17: FALSE | G17: TRUE
B18: 5 | C18: Governance & Risk | D18: Are policy exceptions formally approved and documented? | E18: TRUE | F18: FALSE | G18: TRUE
B19: 6 | C19: Governance & Risk | D19: Are information security risk assessments performed at least annually? | E19: TRUE | F19: FALSE | G19: TRUE
B20: 7 | C20: Governance & Risk | D20: Is risk assessment methodology formally documented? | E20: TRUE | F20: FALSE | G20: TRUE
B21: 8 | C21: Governance & Risk | D21: Are identified risks tracked to remediation? | E21: TRUE | F21: FALSE | G21: TRUE
B22: 9 | C22: Governance & Risk | D22: Does risk assessment include third-party and supply chain risks? | E22: TRUE | F22: FALSE | G22: TRUE
B23: 10 | C23: Governance & Risk | D23: Are residual risks approved by management? | E23: TRUE | F23: FALSE | G23: TRUE
B24: ASSET MANAGEMENT
B25: 11 | C25: Asset Management | D25: Is an inventory of information assets maintained and reviewed? | E25: TRUE | F25: FALSE | G25: TRUE
B26: 12 | C26: Asset Management | D26: Are assets classified based on sensitivity? | E26: TRUE | F26: FALSE | G26: TRUE
B27: 13 | C27: Asset Management | D27: Are asset owners assigned and documented? | E27: TRUE | F27: FALSE | G27: TRUE
B28: 14 | C28: Asset Management | D28: Are acceptable use requirements defined for information assets? | E28: TRUE | F28: FALSE | G28: TRUE
B29: 15 | C29: Asset Management | D29: Is secure disposal of assets enforced? | E29: TRUE | F29: FALSE | G29: TRUE
B30: ACCESS CONTROL & IDENTITY
B31: 16 | C31: Access Control & Identity | D31: Are user accounts uniquely assigned to individuals? | E31: TRUE | F31: FALSE | G31: TRUE
B32: 17 | C32: Access Control & Identity | D32: Is least privilege enforced for system access? | E32: TRUE | F32: FALSE | G32: TRUE
B33: 18 | C33: Access Control & Identity | D33: Are access requests formally approved? | E33: TRUE | F33: FALSE | G33: TRUE
B34: 19 | C34: Access Control & Identity | D34: Is multi-factor authentication implemented where appropriate? | E34: TRUE | F34: FALSE | G34: TRUE
B35: 20 | C35: Access Control & Identity | D35: Are access rights reviewed periodically? | E35: TRUE | F35: FALSE | G35: TRUE
B36: 21 | C36: Access Control & Identity | D36: Are identities uniquely assigned and managed for cloud service access? | E36: TRUE | F36: TRUE | G36: FALSE
B37: 22 | C37: Access Control & Identity | D37: Is multi-factor authentication enforced for privileged access? | E37: TRUE | F37: TRUE | G37: FALSE
B38: 23 | C38: Access Control & Identity | D38: Are authentication mechanisms integrated with centralized identity services? | E38: TRUE | F38: TRUE | G38: FALSE
B39: 24 | C39: Access Control & Identity | D39: Are service accounts managed separately from user accounts? | E39: TRUE | F39: TRUE | G39: FALSE
B40: 25 | C40: Access Control & Identity | D40: What authentication methods are supported for end users (e.g., username/password, SSO, MFA)? | E40: TRUE | F40: TRUE | G40: TRUE
B41: 26 | C41: Access Control & Identity | D41: Do you support single sign-on (SSO) via SAML 2.0 or OAuth 2.0 / OIDC? | E41: TRUE | F41: TRUE | G41: TRUE
B42: 27 | C42: Access Control & Identity | D42: Is multi-factor authentication (MFA) available? Is it enforced or optional? | E42: TRUE | F42: TRUE | G42: TRUE
... B46: 31 | C46: Access Control & Identity | D46: Are access rights reviewed and revoked promptly when an employee changes roles or leaves the organization? | E46: TRUE | F46: TRUE | G46: FALSE
B47: DATA SECURITY & ENCRYPTION
...
